<?xml version="1.0" encoding="utf-8"?>
<!-- This URDF was automatically created by SolidWorks to URDF Exporter! Originally created by Stephen Brawner (brawner@gmail.com) 
     Commit Version: 1.6.0-4-g7f85cfe  Build Version: 1.6.7995.38578
     For more information, please see http://wiki.ros.org/sw_urdf_exporter -->
<robot
  name="reddog" xmlns:xacro="http://www.ros.org/wiki/xacro">
  <ros2_control name="UnitreeSystem" type="system">
    <hardware>
      <plugin>hardware_unitree_mujoco/HardwareUnitree</plugin>
    </hardware>
    <joint name="FR_hip_joint">
      <command_interface name="position"/>
      <command_interface name="velocity"/>
      <command_interface name="effort"/>
      <command_interface name="kp"/>
      <command_interface name="kd"/>
      <state_interface name="position"/>
      <state_interface name="velocity"/>
      <state_interface name="effort"/>
    </joint>
    <joint name="FR_thigh_joint">
      <command_interface name="position"/>
      <command_interface name="velocity"/>
      <command_interface name="effort"/>
      <command_interface name="kp"/>
      <command_interface name="kd"/>
      <state_interface name="position"/>
      <state_interface name="velocity"/>
      <state_interface name="effort"/>
    </joint>
    <joint name="FR_calf_joint">
      <command_interface name="position"/>
      <command_interface name="velocity"/>
      <command_interface name="effort"/>
      <command_interface name="kp"/>
      <command_interface name="kd"/>
      <state_interface name="position"/>
      <state_interface name="velocity"/>
      <state_interface name="effort"/>
    </joint>
    <joint name="FL_hip_joint">
      <command_interface name="position"/>
      <command_interface name="velocity"/>
      <command_interface name="effort"/>
      <command_interface name="kp"/>
      <command_interface name="kd"/>
      <state_interface name="position"/>
      <state_interface name="velocity"/>
      <state_interface name="effort"/>
    </joint>
    <joint name="FL_thigh_joint">
      <command_interface name="position"/>
      <command_interface name="velocity"/>
      <command_interface name="effort"/>
      <command_interface name="kp"/>
      <command_interface name="kd"/>
      <state_interface name="position"/>
      <state_interface name="velocity"/>
      <state_interface name="effort"/>
    </joint>
    <joint name="FL_calf_joint">
      <command_interface name="position"/>
      <command_interface name="velocity"/>
      <command_interface name="effort"/>
      <command_interface name="kp"/>
      <command_interface name="kd"/>
      <state_interface name="position"/>
      <state_interface name="velocity"/>
      <state_interface name="effort"/>
    </joint>
    <joint name="RR_hip_joint">
      <command_interface name="position"/>
      <command_interface name="velocity"/>
      <command_interface name="effort"/>
      <command_interface name="kp"/>
      <command_interface name="kd"/>
      <state_interface name="position"/>
      <state_interface name="velocity"/>
      <state_interface name="effort"/>
    </joint>
    <joint name="RR_thigh_joint">
      <command_interface name="position"/>
      <command_interface name="velocity"/>
      <command_interface name="effort"/>
      <command_interface name="kp"/>
      <command_interface name="kd"/>
      <state_interface name="position"/>
      <state_interface name="velocity"/>
      <state_interface name="effort"/>
    </joint>
    <joint name="RR_calf_joint">
      <command_interface name="position"/>
      <command_interface name="velocity"/>
      <command_interface name="effort"/>
      <command_interface name="kp"/>
      <command_interface name="kd"/>
      <state_interface name="position"/>
      <state_interface name="velocity"/>
      <state_interface name="effort"/>
    </joint>
    <joint name="RL_hip_joint">
      <command_interface name="position"/>
      <command_interface name="velocity"/>
      <command_interface name="effort"/>
      <command_interface name="kp"/>
      <command_interface name="kd"/>
      <state_interface name="position"/>
      <state_interface name="velocity"/>
      <state_interface name="effort"/>
    </joint>
    <joint name="RL_thigh_joint">
      <command_interface name="position"/>
      <command_interface name="velocity"/>
      <command_interface name="effort"/>
      <command_interface name="kp"/>
      <command_interface name="kd"/>
      <state_interface name="position"/>
      <state_interface name="velocity"/>
      <state_interface name="effort"/>
    </joint>
    <joint name="RL_calf_joint">
      <command_interface name="position"/>
      <command_interface name="velocity"/>
      <command_interface name="effort"/>
      <command_interface name="kp"/>
      <command_interface name="kd"/>
      <state_interface name="position"/>
      <state_interface name="velocity"/>
      <state_interface name="effort"/>
    </joint>
    <sensor name="imu_sensor">
      <state_interface name="orientation.w"/>
      <state_interface name="orientation.x"/>
      <state_interface name="orientation.y"/>
      <state_interface name="orientation.z"/>
      <state_interface name="angular_velocity.x"/>
      <state_interface name="angular_velocity.y"/>
      <state_interface name="angular_velocity.z"/>
      <state_interface name="linear_acceleration.x"/>
      <state_interface name="linear_acceleration.y"/>
      <state_interface name="linear_acceleration.z"/>
    </sensor>
    <sensor name="foot_force">
      <state_interface name="FR"/>
      <state_interface name="FL"/>
      <state_interface name="RR"/>
      <state_interface name="RL"/>
    </sensor>
    <sensor name="odometer">
			<state_interface name="position.x"/>
			<state_interface name="position.y"/>
			<state_interface name="position.z"/>
			<state_interface name="velocity.x"/>
			<state_interface name="velocity.y"/>
			<state_interface name="velocity.z"/>
		</sensor>
  </ros2_control>
  <link name="base">
    <visual>
      <origin rpy="0 0 0" xyz="0 0 0"/>
      <geometry>
        <box size="0.001 0.001 0.001"/>
      </geometry>
    </visual>
  </link>
  <joint name="floating_base" type="fixed">
    <origin rpy="0 0 0" xyz="0 0 0"/>
    <parent link="base"/>
    <child link="trunk"/>
  </joint>
  <link
    name="trunk">
    <inertial>
      <origin
        xyz="-0.000178 -0.000021 0.003449"
        rpy="0 0 0" />
      <mass
        value="2.190280" />
      <inertia
        ixx="0.006223"
        ixy="-0.000002"
        ixz="-0.000008"
        iyy="0.019491"
        iyz="-0.000002"
        izz="0.023871" />
    </inertial>
    <visual>
      <origin
        xyz="0 0 0"
        rpy="0 0 0" />
      <geometry>
        <mesh
          filename="package://reddog_description/meshes/base.STL" />
      </geometry>
      <material
        name="">
        <color
          rgba="1 0.02 0.02 0.8" />
      </material>
    </visual>
    <collision>
      <origin
        xyz="0 0 0"
        rpy="0 0 0" />
      <geometry>
        <mesh
          filename="package://reddog_description/meshes/base.STL" />
      </geometry>
    </collision>
  </link>
  <joint name="imu_joint" type="fixed">
    <parent link="trunk"/>
    <child link="imu_link"/>
    <origin rpy="0 0 0" xyz="0 0 0"/>
  </joint>
  <link name="imu_link">
    <inertial>
      <mass value="0.001"/>
      <origin rpy="0 0 0" xyz="0 0 0"/>
      <inertia ixx="0.0001" ixy="0" ixz="0" iyy="0.0001" iyz="0" izz="0.0001"/>
    </inertial>
    <visual>
      <origin rpy="0 0 0" xyz="0 0 0"/>
      <geometry>
        <box size="0.001 0.001 0.001"/>
      </geometry>
      <!-- <material name="red"/> -->
    </visual>
    <collision>
      <origin rpy="0 0 0" xyz="0 0 0"/>
      <geometry>
        <box size=".001 .001 .001"/>
      </geometry>
    </collision>
  </link>
  <link
    name="FR_hip">
    <inertial>
      <origin
        xyz="0.037499 -0.013932 -0.000001"
        rpy="0 0 0" />
      <mass
        value="0.324730" />
      <inertia
        ixx="0.000123"
        ixy="-0.000005"
        ixz="0.000000"
        iyy="0.000140"
        iyz="0.000000"
        izz="0.000130" />
    </inertial>
    <visual>
      <origin
        xyz="0 0 0"
        rpy="0 0 0" />
      <geometry>
        <mesh
          filename="package://reddog_description/meshes/FR_hip.STL" />
      </geometry>
      <material
        name="">
        <color
          rgba="0.05 0.05 0.05 1" />
      </material>
    </visual>
    <!-- <collision>
      <origin
        xyz="0 0 0"
        rpy="0 0 0" />
      <geometry>
        <mesh
          filename="package://reddog_description/meshes/FR_hip.STL" />
      </geometry>
    </collision> -->
  </link>
  <joint
    name="FR_hip_joint"
    type="revolute">
    <origin
      xyz="0.127999974999998 -0.055 0"
      rpy="0 0 0" />
    <parent
      link="base" />
    <child
      link="FR_hip" />
    <axis
      xyz="1 0 0" />
    <limit
      lower="-1.0472"
      upper="1.0472"
      effort="3.0"
      velocity="12.5" />
  </joint>
  <link
    name="FR_thigh">
    <inertial>
      <origin
        xyz="-0.000082 -0.027481 -0.125699"
        rpy="0 0 0" />
      <mass
        value="0.324730" />
      <inertia
        ixx="0.000254"
        ixy="-0.000001"
        ixz="0.000000"
        iyy="0.000267"
        iyz="0.000028"
        izz="0.000122" />
    </inertial>
    <visual>
      <origin
        xyz="0 0 0"
        rpy="0 0 0" />
      <geometry>
        <mesh
          filename="package://reddog_description/meshes/FR_thigh.STL" />
      </geometry>
      <material
        name="">
        <color
          rgba="0.05 0.05 0.05 1" />
      </material>
    </visual>
    <collision>
      <origin
        xyz="0 0 0"
        rpy="0 0 0" />
      <geometry>
        <mesh
          filename="package://reddog_description/meshes/FR_thigh.STL" />
      </geometry>
    </collision>
  </link>
  <joint
    name="FR_thigh_joint"
    type="revolute">
    <origin
      xyz="0.0385000250000002 -0.0374999999999999 0"
      rpy="0 0 0" />
    <parent
      link="FR_hip" />
    <child
      link="FR_thigh" />
    <axis
      xyz="0 1 0" />
    <limit
      lower="0.1"
      upper="1.57"
      effort="3.0"
      velocity="12.5" />
  </joint>
  <link
    name="FR_calf">
    <inertial>
      <origin
        xyz="-0.000098 -0.009599 -0.041140"
        rpy="0 0 0" />
      <mass
        value="0.037400" />
      <inertia
        ixx="0.000069"
        ixy="0.000000"
        ixz="0.000000"
        iyy="0.000076"
        iyz="-0.000002"
        izz="0.000008" />
    </inertial>
    <visual>
      <origin
        xyz="0 0 0"
        rpy="0 0 0" />
      <geometry>
        <mesh
          filename="package://reddog_description/meshes/FR_calf.STL" />
      </geometry>
      <material
        name="">
        <color
          rgba="0.05 0.05 0.05 1" />
      </material>
    </visual>
    <collision>
      <origin
        xyz="0 0 0"
        rpy="0 0 0" />
      <geometry>
        <mesh
          filename="package://reddog_description/meshes/FR_calf.STL" />
      </geometry>
    </collision>
  </link>
  <joint
    name="FR_calf_joint"
    type="revolute">
    <origin
      xyz="0 -0.0409852014855582 -0.130000000000001"
      rpy="0 0 0" />
    <parent
      link="FR_thigh" />
    <child
      link="FR_calf" />
    <axis
      xyz="0 1 0" />
    <limit
      lower="-2.7227"
      upper="-0.3"
      effort="3.0"
      velocity="12.5" />
  </joint>
  <link
    name="FR_foot">
    <inertial>
      <origin
        xyz="-0.000010 -0.009809 -0.001455"
        rpy="0 0 0" />
      <mass
        value="0.010190" />
      <inertia
        ixx="0.000001"
        ixy="0.000000"
        ixz="0.000000"
        iyy="0.000001"
        iyz="0.000000"
        izz="0.000001" />
    </inertial>
    <visual>
      <origin
        xyz="0 0 0"
        rpy="0 0 0" />
      <geometry>
        <mesh
          filename="package://reddog_description/meshes/FR_foot.STL" />
      </geometry>
      <material
        name="">
        <color
          rgba="0.05 0.05 0.05 1" />
      </material>
    </visual>
    <collision>
      <origin
        xyz="0 0 0"
        rpy="0 0 0" />
      <geometry>
        <mesh
          filename="package://reddog_description/meshes/FR_foot.STL" />
      </geometry>
    </collision>
  </link>
  <joint
    name="FR_foot_joint"
    type="fixed" dont_collapse="true">
    <origin
      xyz="0 0 -0.13"
      rpy="0 0 0" />
    <parent
      link="FR_calf" />
    <child
      link="FR_foot" />
    <axis
      xyz="0 1 0" />
  </joint>
  <transmission name="FR_hip_tran">
    <type>transmission_interface/SimpleTransmission</type>
    <joint name="FR_hip_joint">
      <hardwareInterface>hardware_interface/EffortJointInterface</hardwareInterface>
    </joint>
    <actuator name="FR_hip_motor">
      <hardwareInterface>hardware_interface/EffortJointInterface</hardwareInterface>
      <mechanicalReduction>1</mechanicalReduction>
    </actuator>
  </transmission>
  <transmission name="FR_thigh_tran">
    <type>transmission_interface/SimpleTransmission</type>
    <joint name="FR_thigh_joint">
      <hardwareInterface>hardware_interface/EffortJointInterface</hardwareInterface>
    </joint>
    <actuator name="FR_thigh_motor">
      <hardwareInterface>hardware_interface/EffortJointInterface</hardwareInterface>
      <mechanicalReduction>1</mechanicalReduction>
    </actuator>
  </transmission>
  <transmission name="FR_calf_tran">
    <type>transmission_interface/SimpleTransmission</type>
    <joint name="FR_calf_joint">
      <hardwareInterface>hardware_interface/EffortJointInterface</hardwareInterface>
    </joint>
    <actuator name="FR_calf_motor">
      <hardwareInterface>hardware_interface/EffortJointInterface</hardwareInterface>
      <mechanicalReduction>1</mechanicalReduction>
    </actuator>
  </transmission>
  <link
    name="FL_hip">
    <inertial>
      <origin
        xyz="0.037499 0.013932 -0.000001"
        rpy="0 0 0" />
      <mass
        value="0.324730" />
      <inertia
        ixx="0.000123"
        ixy="0.000005"
        ixz="0.000000"
        iyy="0.000140"
        iyz="0.000000"
        izz="0.000130" />
    </inertial>
    <visual>
      <origin
        xyz="0 0 0"
        rpy="0 0 0" />
      <geometry>
        <mesh
          filename="package://reddog_description/meshes/FL_hip.STL" />
      </geometry>
      <material
        name="">
        <color
          rgba="0.05 0.05 0.05 1" />
      </material>
    </visual>
    <!-- <collision>
      <origin
        xyz="0 0 0"
        rpy="0 0 0" />
      <geometry>
        <mesh
          filename="package://reddog_description/meshes/FL_hip.STL" />
      </geometry>
    </collision> -->
  </link>
  <joint
    name="FL_hip_joint"
    type="revolute">
    <origin
      xyz="0.127999974999998 0.055 0"
      rpy="0 0 0" />
    <parent
      link="base" />
    <child
      link="FL_hip" />
    <axis
      xyz="1 0 0" />
    <limit
      lower="-1.0472"
      upper="1.0472"
      effort="3.0"
      velocity="12.5" />
  </joint>
  <link
    name="FL_thigh">
    <inertial>
      <origin
        xyz="-0.000085 0.025358 -0.120119"
        rpy="0 0 0" />
      <mass
        value="0.361700" />
      <inertia
        ixx="0.000463"
        ixy="0.000001"
        ixz="0.000001"
        iyy="0.000469"
        iyz="-0.000065"
        izz="0.000146" />
    </inertial>
    <visual>
      <origin
        xyz="0 0 0"
        rpy="0 0 0" />
      <geometry>
        <mesh
          filename="package://reddog_description/meshes/FL_thigh.STL" />
      </geometry>
      <material
        name="">
        <color
          rgba="0.05 0.05 0.05 1" />
      </material>
    </visual>
    <collision>
      <origin
        xyz="0 0 0"
        rpy="0 0 0" />
      <geometry>
        <mesh
          filename="package://reddog_description/meshes/FL_thigh.STL" />
      </geometry>
    </collision>
  </link>
  <joint
    name="FL_thigh_joint"
    type="revolute">
    <origin
      xyz="0.038500025 0.0375 0"
      rpy="0 0 0" />
    <parent
      link="FL_hip" />
    <child
      link="FL_thigh" />
    <axis
      xyz="0 1 0" />
    <limit
      lower="0.1"
      upper="1.57"
      effort="3.0"
      velocity="12.5" />
  </joint>
  <link
    name="FL_calf">
    <inertial>
      <origin
        xyz="-0.000098 0.009600 -0.041141"
        rpy="0 0 0" />
      <mass
        value="0.037040" />
      <inertia
        ixx="0.000068"
        ixy="0.000000"
        ixz="0.000000"
        iyy="0.000076"
        iyz="0.000002"
        izz="0.000008" />
    </inertial>
    <visual>
      <origin
        xyz="0 0 0"
        rpy="0 0 0" />
      <geometry>
        <mesh
          filename="package://reddog_description/meshes/FL_calf.STL" />
      </geometry>
      <material
        name="">
        <color
          rgba="0.05 0.05 0.05 1" />
      </material>
    </visual>
    <collision>
      <origin
        xyz="0 0 0"
        rpy="0 0 0" />
      <geometry>
        <mesh
          filename="package://reddog_description/meshes/FL_calf.STL" />
      </geometry>
    </collision>
  </link>
  <joint
    name="FL_calf_joint"
    type="revolute">
    <origin
      xyz="0 0.0409852014855581 -0.130000000000001"
      rpy="0 0 0" />
    <parent
      link="FL_thigh" />
    <child
      link="FL_calf" />
    <axis
      xyz="0 1 0" />
    <limit
      lower="-2.7227"
      upper="-0.3"
      effort="3.0"
      velocity="12.5" />
  </joint>
  <link
    name="FL_foot">
    <inertial>
      <origin
        xyz="-0.000010 0.009809 -0.001455"
        rpy="0 0 0" />
      <mass
        value="0.010190" />
      <inertia
        ixx="0.000001"
        ixy="0.000000"
        ixz="0.000000"
        iyy="0.000001"
        iyz="0.000000"
        izz="0.000001" />
    </inertial>
    <visual>
      <origin
        xyz="0 0 0"
        rpy="0 0 0" />
      <geometry>
        <mesh
          filename="package://reddog_description/meshes/FL_foot.STL" />
      </geometry>
      <material
        name="">
        <color
          rgba="0.05 0.05 0.05 1" />
      </material>
    </visual>
    <collision>
      <origin
        xyz="0 0 0"
        rpy="0 0 0" />
      <geometry>
        <mesh
          filename="package://reddog_description/meshes/FL_foot.STL" />
      </geometry>
    </collision>
  </link>
  <joint
    name="FL_foot_joint"
    type="fixed" dont_collapse="true">
    <origin
      xyz="0 0 -0.13"
      rpy="0 0 0" />
    <parent
      link="FL_calf" />
    <child
      link="FL_foot" />
    <axis
      xyz="0 1 0" />
  </joint>
  <transmission name="FL_hip_tran">
    <type>transmission_interface/SimpleTransmission</type>
    <joint name="FL_hip_joint">
      <hardwareInterface>hardware_interface/EffortJointInterface</hardwareInterface>
    </joint>
    <actuator name="FL_hip_motor">
      <hardwareInterface>hardware_interface/EffortJointInterface</hardwareInterface>
      <mechanicalReduction>1</mechanicalReduction>
    </actuator>
  </transmission>
  <transmission name="FL_thigh_tran">
    <type>transmission_interface/SimpleTransmission</type>
    <joint name="FL_thigh_joint">
      <hardwareInterface>hardware_interface/EffortJointInterface</hardwareInterface>
    </joint>
    <actuator name="FL_thigh_motor">
      <hardwareInterface>hardware_interface/EffortJointInterface</hardwareInterface>
      <mechanicalReduction>1</mechanicalReduction>
    </actuator>
  </transmission>
  <transmission name="FL_calf_tran">
    <type>transmission_interface/SimpleTransmission</type>
    <joint name="FL_calf_joint">
      <hardwareInterface>hardware_interface/EffortJointInterface</hardwareInterface>
    </joint>
    <actuator name="FL_calf_motor">
      <hardwareInterface>hardware_interface/EffortJointInterface</hardwareInterface>
      <mechanicalReduction>1</mechanicalReduction>
    </actuator>
  </transmission>
  <link
    name="RR_hip">
    <inertial>
      <origin
        xyz="-0.037499 -0.013932 0.000001"
        rpy="0 0 0" />
      <mass
        value="0.324730" />
      <inertia
        ixx="0.000123"
        ixy="0.000005"
        ixz="0.000000"
        iyy="0.000140"
        iyz="0.000000"
        izz="0.000130" />
    </inertial>
    <visual>
      <origin
        xyz="0 0 0"
        rpy="0 0 0" />
      <geometry>
        <mesh
          filename="package://reddog_description/meshes/RR_hip.STL" />
      </geometry>
      <material
        name="">
        <color
          rgba="0.05 0.05 0.05 1" />
      </material>
    </visual>
    <!-- <collision>
      <origin
        xyz="0 0 0"
        rpy="0 0 0" />
      <geometry>
        <mesh
          filename="package://reddog_description/meshes/RR_hip.STL" />
      </geometry>
    </collision> -->
  </link>
  <joint
    name="RR_hip_joint"
    type="revolute">
    <origin
      xyz="-0.127999975000002 -0.055 0"
      rpy="0 0 0" />
    <parent
      link="base" />
    <child
      link="RR_hip" />
    <axis
      xyz="1 0 0" />
    <limit
      lower="-1.0472"
      upper="1.0472"
      effort="3.0"
      velocity="12.5" />
  </joint>
  <link
    name="RR_thigh">
    <inertial>
      <origin
        xyz="-0.000085 -0.025358 -0.120120"
        rpy="0 0 0" />
      <mass
        value="0.361700" />
      <inertia
        ixx="0.000463"
        ixy="-0.000001"
        ixz="0.000001"
        iyy="0.000469"
        iyz="0.000064"
        izz="0.000146" />
    </inertial>
    <visual>
      <origin
        xyz="0 0 0"
        rpy="0 0 0" />
      <geometry>
        <mesh
          filename="package://reddog_description/meshes/RR_thigh.STL" />
      </geometry>
      <material
        name="">
        <color
          rgba="0.05 0.05 0.05 1" />
      </material>
    </visual>
    <collision>
      <origin
        xyz="0 0 0"
        rpy="0 0 0" />
      <geometry>
        <mesh
          filename="package://reddog_description/meshes/RR_thigh.STL" />
      </geometry>
    </collision>
  </link>
  <joint
    name="RR_thigh_joint"
    type="revolute">
    <origin
      xyz="-0.0385000250000012 -0.0374999999999921 0"
      rpy="0 0 0" />
    <parent
      link="RR_hip" />
    <child
      link="RR_thigh" />
    <axis
      xyz="0 1 0" />
    <limit
      lower="-1.57"
      upper="-0.1"
      effort="3.0"
      velocity="12.5" />
  </joint>
  <link
    name="RR_calf">
    <inertial>
      <origin
        xyz="-0.000098 -0.009599 -0.041140"
        rpy="0 0 0" />
      <mass
        value="0.037400" />
      <inertia
        ixx="0.000069"
        ixy="0.000000"
        ixz="0.000000"
        iyy="0.000076"
        iyz="-0.000002"
        izz="0.000008" />
    </inertial>
    <visual>
      <origin
        xyz="0 0 0"
        rpy="0 0 0" />
      <geometry>
        <mesh
          filename="package://reddog_description/meshes/RR_calf.STL" />
      </geometry>
      <material
        name="">
        <color
          rgba="0.05 0.05 0.05 1" />
      </material>
    </visual>
    <collision>
      <origin
        xyz="0 0 0"
        rpy="0 0 0" />
      <geometry>
        <mesh
          filename="package://reddog_description/meshes/RR_calf.STL" />
      </geometry>
    </collision>
  </link>
  <joint
    name="RR_calf_joint"
    type="revolute">
    <origin
      xyz="0 -0.040985201485548 -0.130000000000005"
      rpy="0 0 0" />
    <parent
      link="RR_thigh" />
    <child
      link="RR_calf" />
    <axis
      xyz="0 1 0" />
    <limit
      lower="0.3"
      upper="2.7227"
      effort="3.0"
      velocity="12.5" />
  </joint>
  <link
    name="RR_foot">
    <inertial>
      <origin
        xyz="-0.000010 -0.009809 -0.001455"
        rpy="0 0 0" />
      <mass
        value="0.010190" />
      <inertia
        ixx="0.000001"
        ixy="0.000000"
        ixz="0.000000"
        iyy="0.000001"
        iyz="0.000000"
        izz="0.000001" />
    </inertial>
    <visual>
      <origin
        xyz="0 0 0"
        rpy="0 0 0" />
      <geometry>
        <mesh
          filename="package://reddog_description/meshes/RR_foot.STL" />
      </geometry>
      <material
        name="">
        <color
          rgba="0.05 0.05 0.05 1" />
      </material>
    </visual>
    <collision>
      <origin
        xyz="0 0 0"
        rpy="0 0 0" />
      <geometry>
        <mesh
          filename="package://reddog_description/meshes/RR_foot.STL" />
      </geometry>
    </collision>
  </link>
  <joint
    name="RR_foot_joint"
    type="fixed" dont_collapse="true">
    <origin
      xyz="0 0 -0.130000000000004"
      rpy="0 0 0" />
    <parent
      link="RR_calf" />
    <child
      link="RR_foot" />
    <axis
      xyz="0 1 0" />
  </joint>
  <transmission name="RR_hip_tran">
    <type>transmission_interface/SimpleTransmission</type>
    <joint name="RR_hip_joint">
      <hardwareInterface>hardware_interface/EffortJointInterface</hardwareInterface>
    </joint>
    <actuator name="RR_hip_motor">
      <hardwareInterface>hardware_interface/EffortJointInterface</hardwareInterface>
      <mechanicalReduction>1</mechanicalReduction>
    </actuator>
  </transmission>
  <transmission name="RR_thigh_tran">
    <type>transmission_interface/SimpleTransmission</type>
    <joint name="RR_thigh_joint">
      <hardwareInterface>hardware_interface/EffortJointInterface</hardwareInterface>
    </joint>
    <actuator name="RR_thigh_motor">
      <hardwareInterface>hardware_interface/EffortJointInterface</hardwareInterface>
      <mechanicalReduction>1</mechanicalReduction>
    </actuator>
  </transmission>
  <transmission name="RR_calf_tran">
    <type>transmission_interface/SimpleTransmission</type>
    <joint name="RR_calf_joint">
      <hardwareInterface>hardware_interface/EffortJointInterface</hardwareInterface>
    </joint>
    <actuator name="RR_calf_motor">
      <hardwareInterface>hardware_interface/EffortJointInterface</hardwareInterface>
      <mechanicalReduction>1</mechanicalReduction>
    </actuator>
  </transmission>
  <link
    name="RL_hip">
    <inertial>
      <origin
        xyz="-0.037499 0.013932 0.000001"
        rpy="0 0 0" />
      <mass
        value="0.324730" />
      <inertia
        ixx="0.000123"
        ixy="-0.000005"
        ixz="0.000000"
        iyy="0.000140"
        iyz="0.000000"
        izz="0.000130" />
    </inertial>
    <visual>
      <origin
        xyz="0 0 0"
        rpy="0 0 0" />
      <geometry>
        <mesh
          filename="package://reddog_description/meshes/RL_hip.STL" />
      </geometry>
      <material
        name="">
        <color
          rgba="0.05 0.05 0.05 1" />
      </material>
    </visual>
    <!-- <collision>
      <origin
        xyz="0 0 0"
        rpy="0 0 0" />
      <geometry>
        <mesh
          filename="package://reddog_description/meshes/RL_hip.STL" />
      </geometry>
    </collision> -->
  </link>
  <joint
    name="RL_hip_joint"
    type="revolute">
    <origin
      xyz="-0.127999974999999 0.054999999999999 0"
      rpy="0 0 0" />
    <parent
      link="base" />
    <child
      link="RL_hip" />
    <axis
      xyz="1 0 0" />
    <limit
      lower="-1.0472"
      upper="1.0472"
      effort="3.0"
      velocity="12.5" />
  </joint>
  <link
    name="RL_thigh">
    <inertial>
      <origin
        xyz="-0.000085 0.025358 -0.120119"
        rpy="0 0 0" />
      <mass
        value="0.361700" />
      <inertia
        ixx="0.000463"
        ixy="0.000001"
        ixz="0.000001"
        iyy="0.000469"
        iyz="-0.000065"
        izz="0.000146" />
    </inertial>
    <visual>
      <origin
        xyz="0 0 0"
        rpy="0 0 0" />
      <geometry>
        <mesh
          filename="package://reddog_description/meshes/RL_thigh.STL" />
      </geometry>
      <material
        name="">
        <color
          rgba="0.05 0.05 0.05 1" />
      </material>
    </visual>
    <collision>
      <origin
        xyz="0 0 0"
        rpy="0 0 0" />
      <geometry>
        <mesh
          filename="package://reddog_description/meshes/RL_thigh.STL" />
      </geometry>
    </collision>
  </link>
  <joint
    name="RL_thigh_joint"
    type="revolute">
    <origin
      xyz="-0.0385000249999999 0.0374999999999952 0"
      rpy="0 0 0" />
    <parent
      link="RL_hip" />
    <child
      link="RL_thigh" />
    <axis
      xyz="0 1 0" />
    <limit
      lower="-1.57"
      upper="0.1"
      effort="3.0"
      velocity="12.5" />
  </joint>
  <link
    name="RL_calf">
    <inertial>
      <origin
        xyz="-0.000098 0.009600 -0.041141"
        rpy="0 0 0" />
      <mass
        value="0.037400" />
      <inertia
        ixx="0.000069"
        ixy="0.000000"
        ixz="0.000000"
        iyy="0.000076"
        iyz="0.000002"
        izz="0.000008" />
    </inertial>
    <visual>
      <origin
        xyz="0 0 0"
        rpy="0 0 0" />
      <geometry>
        <mesh
          filename="package://reddog_description/meshes/RL_calf.STL" />
      </geometry>
      <material
        name="">
        <color
          rgba="0.05 0.05 0.05 1" />
      </material>
    </visual>
    <collision>
      <origin
        xyz="0 0 0"
        rpy="0 0 0" />
      <geometry>
        <mesh
          filename="package://reddog_description/meshes/RL_calf.STL" />
      </geometry>
    </collision>
  </link>
  <joint
    name="RL_calf_joint"
    type="revolute">
    <origin
      xyz="0 0.0409852014855523 -0.130000000000005"
      rpy="0 0 0" />
    <parent
      link="RL_thigh" />
    <child
      link="RL_calf" />
    <axis
      xyz="0 1 0" />
    <limit
      lower="0.3"
      upper="2.7227"
      effort="3.0"
      velocity="12.5" />
  </joint>
  <link
    name="RL_foot">
    <inertial>
      <origin
        xyz="-0.000010 0.009809 -0.001455"
        rpy="0 0 0" />
      <mass
        value="0.010190" />
      <inertia
        ixx="0.000001"
        ixy="0.000000"
        ixz="0.000000"
        iyy="0.000001"
        iyz="0.000000"
        izz="0.000001" />
    </inertial>
    <visual>
      <origin
        xyz="0 0 0"
        rpy="0 0 0" />
      <geometry>
        <mesh
          filename="package://reddog_description/meshes/RL_foot.STL" />
      </geometry>
      <material
        name="">
        <color
          rgba="0.05 0.05 0.05 1" />
      </material>
    </visual>
    <collision>
      <origin
        xyz="0 0 0"
        rpy="0 0 0" />
      <geometry>
        <mesh
          filename="package://reddog_description/meshes/RL_foot.STL" />
      </geometry>
    </collision>
  </link>
  <joint
    name="RL_foot_joint"
    type="fixed" dont_collapse="true">
    <origin
      xyz="0 0 -0.130000000000004"
      rpy="0 0 0" />
    <parent
      link="RL_calf" />
    <child
      link="RL_foot" />
    <axis
      xyz="0 1 0" />
  </joint>
  <transmission name="RL_hip_tran">
    <type>transmission_interface/SimpleTransmission</type>
    <joint name="RL_hip_joint">
      <hardwareInterface>hardware_interface/EffortJointInterface</hardwareInterface>
    </joint>
    <actuator name="RL_hip_motor">
      <hardwareInterface>hardware_interface/EffortJointInterface</hardwareInterface>
      <mechanicalReduction>1</mechanicalReduction>
    </actuator>
  </transmission>
  <transmission name="RL_thigh_tran">
    <type>transmission_interface/SimpleTransmission</type>
    <joint name="RL_thigh_joint">
      <hardwareInterface>hardware_interface/EffortJointInterface</hardwareInterface>
    </joint>
    <actuator name="RL_thigh_motor">
      <hardwareInterface>hardware_interface/EffortJointInterface</hardwareInterface>
      <mechanicalReduction>1</mechanicalReduction>
    </actuator>
  </transmission>
  <transmission name="RL_calf_tran">
    <type>transmission_interface/SimpleTransmission</type>
    <joint name="RL_calf_joint">
      <hardwareInterface>hardware_interface/EffortJointInterface</hardwareInterface>
    </joint>
    <actuator name="RL_calf_motor">
      <hardwareInterface>hardware_interface/EffortJointInterface</hardwareInterface>
      <mechanicalReduction>1</mechanicalReduction>
    </actuator>
  </transmission>
</robot>
